<?xml version="1.0" encoding="utf-8"?>
<!-- This URDF was automatically created by SolidWorks to URDF Exporter! Originally created by Stephen Brawner (brawner@gmail.com) 
     Commit Version: 1.6.0-4-g7f85cfe  Build Version: 1.6.7995.38578
     For more information, please see http://wiki.ros.org/sw_urdf_exporter -->
<robot
  name="outdoor_robot_signal_antenna">
  <link
    name="base_link">
    <inertial>
      <origin
        xyz="-0.074353 0.015107 0.075824"
        rpy="0 0 0" />
      <mass
        value="11.902" />
      <inertia
        ixx="0.1269"
        ixy="6.3806E-05"
        ixz="-0.00080196"
        iyy="0.085732"
        iyz="-2.0152E-05"
        izz="0.18939" />
    </inertial>
    <visual>
      <origin
        xyz="0 0 0"
        rpy="0 0 0" />
      <geometry>
        <mesh
          filename="package://wheeltec_robot_urdf/meshes/autoware_top_akm_single_antenna_meshes/base_link.STL" />
      </geometry>
      <material
        name="">
        <color
          rgba="0.74118 0.90196 0.95686 1" />
      </material>
    </visual>
    <collision>
      <origin
        xyz="0 0 0"
        rpy="0 0 0" />
      <geometry>
        <mesh
          filename="package://wheeltec_robot_urdf/meshes/autoware_top_akm_single_antenna_meshes/base_link.STL" />
      </geometry>
    </collision>
  </link>
  <link
    name="lf_wheel_link">
    <inertial>
      <origin
        xyz="2.0036E-05 -0.0022382 0.0002117"
        rpy="0 0 0" />
      <mass
        value="1.102" />
      <inertia
        ixx="0.0060143"
        ixy="-4.5815E-05"
        ixz="-1.3207E-07"
        iyy="0.010609"
        iyz="1.3337E-05"
        izz="0.0060142" />
    </inertial>
    <visual>
      <origin
        xyz="0 0 0"
        rpy="0 0 0" />
      <geometry>
        <mesh
          filename="package://wheeltec_robot_urdf/meshes/autoware_top_akm_single_antenna_meshes/lf_wheel_link.STL" />
      </geometry>
      <material
        name="">
        <color
          rgba="1 1 1 1" />
      </material>
    </visual>
    <collision>
      <origin
        xyz="0 0 0"
        rpy="0 0 0" />
      <geometry>
        <mesh
          filename="package://wheeltec_robot_urdf/meshes/autoware_top_akm_single_antenna_meshes/lf_wheel_link.STL" />
      </geometry>
    </collision>
  </link>
  <joint
    name="lf_wheel_joint"
    type="continuous">
    <origin
      xyz="0.31528 0.29699 0.0066081"
      rpy="0 0 0" />
    <parent
      link="base_link" />
    <child
      link="lf_wheel_link" />
    <axis
      xyz="-0.0099394 0.99995 -0.0028981" />
  </joint>
  <link
    name="lb_wheel_link">
    <inertial>
      <origin
        xyz="-3.0408E-06 -0.002239 0.00020377"
        rpy="0 0 0" />
      <mass
        value="1.102" />
      <inertia
        ixx="0.0060138"
        ixy="-1.2787E-08"
        ixz="-1.7251E-10"
        iyy="0.010609"
        iyz="2.9601E-05"
        izz="0.0060143" />
    </inertial>
    <visual>
      <origin
        xyz="0 0 0"
        rpy="0 0 0" />
      <geometry>
        <mesh
          filename="package://wheeltec_robot_urdf/meshes/autoware_top_akm_single_antenna_meshes/lb_wheel_link.STL" />
      </geometry>
      <material
        name="">
        <color
          rgba="1 1 1 1" />
      </material>
    </visual>
    <collision>
      <origin
        xyz="0 0 0"
        rpy="0 0 0" />
      <geometry>
        <mesh
          filename="package://wheeltec_robot_urdf/meshes/autoware_top_akm_single_antenna_meshes/lb_wheel_link.STL" />
      </geometry>
    </collision>
  </link>
  <joint
    name="lb_wheel_joint"
    type="continuous">
    <origin
      xyz="-0.21055 0.29728 0.0050309"
      rpy="0 0 0" />
    <parent
      link="base_link" />
    <child
      link="lb_wheel_link" />
    <axis
      xyz="0 0.99998 -0.0064377" />
  </joint>
  <link
    name="rf_wheel_link">
    <inertial>
      <origin
        xyz="-8.2751E-05 0.0022363 -0.00021612"
        rpy="0 0 0" />
      <mass
        value="1.102" />
      <inertia
        ixx="0.0060143"
        ixy="-4.5654E-05"
        ixz="2.0461E-07"
        iyy="0.010609"
        iyz="-1.3299E-05"
        izz="0.0060142" />
    </inertial>
    <visual>
      <origin
        xyz="0 0 0"
        rpy="0 0 0" />
      <geometry>
        <mesh
          filename="package://wheeltec_robot_urdf/meshes/autoware_top_akm_single_antenna_meshes/rf_wheel_link.STL" />
      </geometry>
      <material
        name="">
        <color
          rgba="1 1 1 1" />
      </material>
    </visual>
    <collision>
      <origin
        xyz="0 0 0"
        rpy="0 0 0" />
      <geometry>
        <mesh
          filename="package://wheeltec_robot_urdf/meshes/autoware_top_akm_single_antenna_meshes/rf_wheel_link.STL" />
      </geometry>
    </collision>
  </link>
  <joint
    name="rf_wheel_joint"
    type="continuous">
    <origin
      xyz="0.31685 -0.29694 0.0070471"
      rpy="0 0 0" />
    <parent
      link="base_link" />
    <child
      link="rf_wheel_link" />
    <axis
      xyz="-0.0099394 0.99995 -0.0028981" />
  </joint>
  <link
    name="rb_wheel_joint">
    <inertial>
      <origin
        xyz="2.315E-07 0.002239 0.00020379"
        rpy="0 0 0" />
      <mass
        value="1.102" />
      <inertia
        ixx="0.0060138"
        ixy="-1.2548E-08"
        ixz="-3.4897E-09"
        iyy="0.010609"
        iyz="-2.9601E-05"
        izz="0.0060143" />
    </inertial>
    <visual>
      <origin
        xyz="0 0 0"
        rpy="0 0 0" />
      <geometry>
        <mesh
          filename="package://wheeltec_robot_urdf/meshes/autoware_top_akm_single_antenna_meshes/rb_wheel_joint.STL" />
      </geometry>
      <material
        name="">
        <color
          rgba="1 1 1 1" />
      </material>
    </visual>
    <collision>
      <origin
        xyz="0 0 0"
        rpy="0 0 0" />
      <geometry>
        <mesh
          filename="package://wheeltec_robot_urdf/meshes/autoware_top_akm_single_antenna_meshes/rb_wheel_joint.STL" />
      </geometry>
    </collision>
  </link>
  <joint
    name="rb_wheel_joint"
    type="continuous">
    <origin
      xyz="-0.21055 -0.29724 0.0050309"
      rpy="0 0 0" />
    <parent
      link="base_link" />
    <child
      link="rb_wheel_joint" />
    <axis
      xyz="0 0.99998 -0.0064377" />
  </joint>
  <link
    name="mushroom_link">
    <inertial>
      <origin
        xyz="-1.1432E-06 0.00010848 -0.028981"
        rpy="0 0 0" />
      <mass
        value="0.70507" />
      <inertia
        ixx="0.00083839"
        ixy="9.5781E-11"
        ixz="8.5567E-11"
        iyy="0.00084033"
        iyz="1.1975E-06"
        izz="0.0014378" />
    </inertial>
    <visual>
      <origin
        xyz="0 0 0"
        rpy="0 0 0" />
      <geometry>
        <mesh
          filename="package://wheeltec_robot_urdf/meshes/autoware_top_akm_single_antenna_meshes/mushroom_link.STL" />
      </geometry>
      <material
        name="">
        <color
          rgba="0.75294 0.75294 0.75294 1" />
      </material>
    </visual>
    <collision>
      <origin
        xyz="0 0 0"
        rpy="0 0 0" />
      <geometry>
        <mesh
          filename="package://wheeltec_robot_urdf/meshes/autoware_top_akm_single_antenna_meshes/mushroom_link.STL" />
      </geometry>
    </collision>
  </link>
  <joint
    name="mushroom_joint"
    type="fixed">
    <origin
      xyz="-0.12171 2.3862E-05 0.4197"
      rpy="0 0 0" />
    <parent
      link="base_link" />
    <child
      link="mushroom_link" />
    <axis
      xyz="0 0 0" />
  </joint>
  <link
    name="laser_link">
    <inertial>
      <origin
        xyz="-0.00048925 -1.7832E-05 0.0027116"
        rpy="0 0 0" />
      <mass
        value="0.28408" />
      <inertia
        ixx="0.00069265"
        ixy="-2.2006E-08"
        ixz="-5.1015E-06"
        iyy="0.00070191"
        iyz="-5.5999E-08"
        izz="0.000772" />
    </inertial>
    <visual>
      <origin
        xyz="0 0 0"
        rpy="0 0 0" />
      <geometry>
        <mesh
          filename="package://wheeltec_robot_urdf/meshes/autoware_top_akm_single_antenna_meshes/laser_link.STL" />
      </geometry>
      <material
        name="">
        <color
          rgba="0.74118 0.90196 0.95686 1" />
      </material>
    </visual>
    <collision>
      <origin
        xyz="0 0 0"
        rpy="0 0 0" />
      <geometry>
        <mesh
          filename="package://wheeltec_robot_urdf/meshes/autoware_top_akm_single_antenna_meshes/laser_link.STL" />
      </geometry>
    </collision>
  </link>
  <joint
    name="laser_joint"
    type="fixed">
    <origin
      xyz="0.17378 2.375E-05 0.3965"
      rpy="0 0 0" />
    <parent
      link="base_link" />
    <child
      link="laser_link" />
    <axis
      xyz="0 0 0" />
  </joint>
  <link
    name="camera_link">
    <inertial>
      <origin
        xyz="2.9259E-07 -6.1582E-09 3.674E-07"
        rpy="0 0 0" />
      <mass
        value="0.056458" />
      <inertia
        ixx="0.00013086"
        ixy="1.2038E-07"
        ixz="1.6474E-06"
        iyy="1.9178E-05"
        iyz="-2.8268E-08"
        izz="0.0001314" />
    </inertial>
    <visual>
      <origin
        xyz="0 0 0"
        rpy="0 0 0" />
      <geometry>
        <mesh
          filename="package://wheeltec_robot_urdf/meshes/autoware_top_akm_single_antenna_meshes/camera_link.STL" />
      </geometry>
      <material
        name="">
        <color
          rgba="0.37647 0.37647 0.37647 1" />
      </material>
    </visual>
    <collision>
      <origin
        xyz="0 0 0"
        rpy="0 0 0" />
      <geometry>
        <mesh
          filename="package://wheeltec_robot_urdf/meshes/autoware_top_akm_single_antenna_meshes/camera_link.STL" />
      </geometry>
    </collision>
  </link>
  <joint
    name="camera_joint"
    type="fixed">
    <origin
      xyz="0.3557 0.00020075 0.16458"
      rpy="0 0 0" />
    <parent
      link="base_link" />
    <child
      link="camera_link" />
    <axis
      xyz="0 0 0" />
  </joint>
</robot>
