<?xml version="1.0" encoding="utf-8"?>
<!-- This URDF was automatically created by SolidWorks to URDF Exporter! Originally created by Stephen Brawner (brawner@gmail.com) 
     Commit Version: 1.6.0-4-g7f85cfe  Build Version: 1.6.7995.38578
     For more information, please see http://wiki.ros.org/sw_urdf_exporter -->
<robot
  name="outdoor_robot_dual_antenna">
  <link
    name="base_link">
    <inertial>
      <origin
        xyz="-0.07201 0.014272 0.080504"
        rpy="0 0 0" />
      <mass
        value="12.258" />
      <inertia
        ixx="0.12737"
        ixy="6.3543E-05"
        ixz="-0.00080332"
        iyy="0.087659"
        iyz="-2.0279E-05"
        izz="0.19113" />
    </inertial>
    <visual>
      <origin
        xyz="0 0 0"
        rpy="0 0 0" />
      <geometry>
        <mesh
          filename="package://wheeltec_robot_urdf/meshes/autoware_top_akm_dual_antenna_meshes/base_link.STL" />
      </geometry>
      <material
        name="">
        <color
          rgba="0.74118 0.90196 0.95686 1" />
      </material>
    </visual>
    <collision>
      <origin
        xyz="0 0 0"
        rpy="0 0 0" />
      <geometry>
        <mesh
          filename="package://wheeltec_robot_urdf/meshes/autoware_top_akm_dual_antenna_meshes/base_link.STL" />
      </geometry>
    </collision>
  </link>
  <link
    name="rf_wheel_link">
    <inertial>
      <origin
        xyz="-8.2724E-05 0.0022363 -0.00021614"
        rpy="0 0 0" />
      <mass
        value="1.102" />
      <inertia
        ixx="0.0060143"
        ixy="-4.5653E-05"
        ixz="2.0628E-07"
        iyy="0.010609"
        iyz="-1.33E-05"
        izz="0.0060142" />
    </inertial>
    <visual>
      <origin
        xyz="0 0 0"
        rpy="0 0 0" />
      <geometry>
        <mesh
          filename="package://wheeltec_robot_urdf/meshes/autoware_top_akm_dual_antenna_meshes/rf_wheel_link.STL" />
      </geometry>
      <material
        name="">
        <color
          rgba="1 1 1 1" />
      </material>
    </visual>
    <collision>
      <origin
        xyz="0 0 0"
        rpy="0 0 0" />
      <geometry>
        <mesh
          filename="package://wheeltec_robot_urdf/meshes/autoware_top_akm_dual_antenna_meshes/rf_wheel_link.STL" />
      </geometry>
    </collision>
  </link>
  <joint
    name="rf_wheel_joint"
    type="continuous">
    <origin
      xyz="0.31685 -0.29694 0.0070471"
      rpy="0 0 0" />
    <parent
      link="base_link" />
    <child
      link="rf_wheel_link" />
    <axis
      xyz="0.0099678 -0.99995 -0.0028981" />
  </joint>
  <link
    name="rb_wheel_link">
    <inertial>
      <origin
        xyz="1.99742685613735E-07 0.00223897036079174 0.00020380004580535"
        rpy="0 0 0" />
      <mass
        value="1.10203492512855" />
      <inertia
        ixx="0.00601385054971674"
        ixy="-1.32836436860679E-08"
        ixz="-2.30876145541355E-09"
        iyy="0.0106089480246942"
        iyz="-2.96008728378449E-05"
        izz="0.00601432799521864" />
    </inertial>
    <visual>
      <origin
        xyz="0 0 0"
        rpy="0 0 0" />
      <geometry>
        <mesh
          filename="package://wheeltec_robot_urdf/meshes/autoware_top_akm_dual_antenna_meshes/rb_wheel_link.STL" />
      </geometry>
      <material
        name="">
        <color
          rgba="1 1 1 1" />
      </material>
    </visual>
    <collision>
      <origin
        xyz="0 0 0"
        rpy="0 0 0" />
      <geometry>
        <mesh
          filename="package://wheeltec_robot_urdf/meshes/autoware_top_akm_dual_antenna_meshes/rb_wheel_link.STL" />
      </geometry>
    </collision>
  </link>
  <joint
    name="rb_wheel_joint"
    type="continuous">
    <origin
      xyz="-0.21055 -0.29724 0.0050309"
      rpy="0 0 0" />
    <parent
      link="base_link" />
    <child
      link="rb_wheel_link" />
    <axis
      xyz="0 0.99998 -0.0064377" />
  </joint>
  <link
    name="lf_wheel_link">
    <inertial>
      <origin
        xyz="2.00675460826361E-05 -0.00223814609587303 0.000211713676485883"
        rpy="0 0 0" />
      <mass
        value="1.102034925596" />
      <inertia
        ixx="0.00601430737082184"
        ixy="-4.58157485536663E-05"
        ixz="-1.3327001802482E-07"
        iyy="0.0106086431733912"
        iyz="1.33362442070962E-05"
        izz="0.00601417603084709" />
    </inertial>
    <visual>
      <origin
        xyz="0 0 0"
        rpy="0 0 0" />
      <geometry>
        <mesh
          filename="package://wheeltec_robot_urdf/meshes/autoware_top_akm_dual_antenna_meshes/lf_wheel_link.STL" />
      </geometry>
      <material
        name="">
        <color
          rgba="1 1 1 1" />
      </material>
    </visual>
    <collision>
      <origin
        xyz="0 0 0"
        rpy="0 0 0" />
      <geometry>
        <mesh
          filename="package://wheeltec_robot_urdf/meshes/autoware_top_akm_dual_antenna_meshes/lf_wheel_link.STL" />
      </geometry>
    </collision>
  </link>
  <joint
    name="lf_wheel_joint"
    type="continuous">
    <origin
      xyz="0.31528 0.29699 0.0066081"
      rpy="0 0 0" />
    <parent
      link="base_link" />
    <child
      link="lf_wheel_link" />
    <axis
      xyz="0.0099678 -0.99995 -0.0028981" />
  </joint>
  <link
    name="lb_wheel_link">
    <inertial>
      <origin
        xyz="-3.00921013823841E-06 -0.00223897022781205 0.000203779393032247"
        rpy="0 0 0" />
      <mass
        value="1.10203492512723" />
      <inertia
        ixx="0.00601385053560425"
        ixy="-1.35187166532443E-08"
        ixz="-1.38526343147151E-09"
        iyy="0.010608948026917"
        iyz="2.96007001899775E-05"
        izz="0.00601432800710883" />
    </inertial>
    <visual>
      <origin
        xyz="0 0 0"
        rpy="0 0 0" />
      <geometry>
        <mesh
          filename="package://wheeltec_robot_urdf/meshes/autoware_top_akm_dual_antenna_meshes/lb_wheel_link.STL" />
      </geometry>
      <material
        name="">
        <color
          rgba="1 1 1 1" />
      </material>
    </visual>
    <collision>
      <origin
        xyz="0 0 0"
        rpy="0 0 0" />
      <geometry>
        <mesh
          filename="package://wheeltec_robot_urdf/meshes/autoware_top_akm_dual_antenna_meshes/lb_wheel_link.STL" />
      </geometry>
    </collision>
  </link>
  <joint
    name="lb_wheel_joint"
    type="continuous">
    <origin
      xyz="-0.21055 0.29728 0.0050309"
      rpy="0 0 0" />
    <parent
      link="base_link" />
    <child
      link="lb_wheel_link" />
    <axis
      xyz="0 0.99998 -0.0064377" />
  </joint>
  <link
    name="laser_link">
    <inertial>
      <origin
        xyz="-0.00019975838804856 -5.62033299802578E-06 0.0092747115861298"
        rpy="0 0 0" />
      <mass
        value="1.28006007522406" />
      <inertia
        ixx="0.00169622594656528"
        ixy="-2.17603717086209E-08"
        ixz="-8.58943182701468E-06"
        iyy="0.0017123703921267"
        iyz="-1.31977604062403E-07"
        izz="0.00204500985119737" />
    </inertial>
    <visual>
      <origin
        xyz="0 0 0"
        rpy="0 0 0" />
      <geometry>
        <mesh
          filename="package://wheeltec_robot_urdf/meshes/autoware_top_akm_dual_antenna_meshes/laser_link.STL" />
      </geometry>
      <material
        name="">
        <color
          rgba="0.752941176470588 0.752941176470588 0.752941176470588 1" />
      </material>
    </visual>
    <collision>
      <origin
        xyz="0 0 0"
        rpy="0 0 0" />
      <geometry>
        <mesh
          filename="package://wheeltec_robot_urdf/meshes/autoware_top_akm_dual_antenna_meshes/laser_link.STL" />
      </geometry>
    </collision>
  </link>
  <joint
    name="laser_joint"
    type="fixed">
    <origin
      xyz="0.17378 2.375E-05 0.3965"
      rpy="0 0 0" />
    <parent
      link="base_link" />
    <child
      link="laser_link" />
    <axis
      xyz="0 0 0" />
  </joint>
  <link
    name="camera_link">
    <inertial>
      <origin
        xyz="2.92587957917423E-07 0.000353993845807704 3.674048406066E-07"
        rpy="0 0 0" />
      <mass
        value="0.056458220481529" />
      <inertia
        ixx="0.000130864623434555"
        ixy="1.20384350303155E-07"
        ixz="1.6474427272883E-06"
        iyy="1.91783298717298E-05"
        iyz="-2.82675726788762E-08"
        izz="0.000131402505525389" />
    </inertial>
    <visual>
      <origin
        xyz="0 0 0"
        rpy="0 0 0" />
      <geometry>
        <mesh
          filename="package://wheeltec_robot_urdf/meshes/autoware_top_akm_dual_antenna_meshes/camera_link.STL" />
      </geometry>
      <material
        name="">
        <color
          rgba="0.376470588235294 0.376470588235294 0.376470588235294 1" />
      </material>
    </visual>
    <collision>
      <origin
        xyz="0 0 0"
        rpy="0 0 0" />
      <geometry>
        <mesh
          filename="package://wheeltec_robot_urdf/meshes/autoware_top_akm_dual_antenna_meshes/camera_link.STL" />
      </geometry>
    </collision>
  </link>
  <joint
    name="camera_joint"
    type="fixed">
    <origin
      xyz="0.3557 -0.00015325 0.16458"
      rpy="0 0 0" />
    <parent
      link="base_link" />
    <child
      link="camera_link" />
    <axis
      xyz="0 0 0" />
  </joint>
  <link
    name="left_mushroom_link">
    <inertial>
      <origin
        xyz="1.14319527430573E-06 -0.000108481007837335 -0.0289810907638313"
        rpy="0 0 0" />
      <mass
        value="0.705067820296359" />
      <inertia
        ixx="0.000838392865016739"
        ixy="9.57809994964931E-11"
        ixz="-8.55672766684439E-11"
        iyy="0.000840325925806544"
        iyz="-1.19748582928506E-06"
        izz="0.00143784262541869" />
    </inertial>
    <visual>
      <origin
        xyz="0 0 0"
        rpy="0 0 0" />
      <geometry>
        <mesh
          filename="package://wheeltec_robot_urdf/meshes/autoware_top_akm_dual_antenna_meshes/left_mushroom_link.STL" />
      </geometry>
      <material
        name="">
        <color
          rgba="1 1 1 1" />
      </material>
    </visual>
    <collision>
      <origin
        xyz="0 0 0"
        rpy="0 0 0" />
      <geometry>
        <mesh
          filename="package://wheeltec_robot_urdf/meshes/autoware_top_akm_dual_antenna_meshes/left_mushroom_link.STL" />
      </geometry>
    </collision>
  </link>
  <joint
    name="left_mushroom_joint"
    type="fixed">
    <origin
      xyz="-0.13979 0.26011 0.4187"
      rpy="0 0 0" />
    <parent
      link="base_link" />
    <child
      link="left_mushroom_link" />
    <axis
      xyz="0 0 0" />
  </joint>
  <link
    name="right_mushroom_link">
    <inertial>
      <origin
        xyz="0 0 0"
        rpy="0 0 0" />
      <mass
        value="0" />
      <inertia
        ixx="0"
        ixy="0"
        ixz="0"
        iyy="0"
        iyz="0"
        izz="0" />
    </inertial>
    <visual>
      <origin
        xyz="0 0 0"
        rpy="0 0 0" />
      <geometry>
        <mesh
          filename="package://wheeltec_robot_urdf/meshes/autoware_top_akm_dual_antenna_meshes/right_mushroom_link.STL" />
      </geometry>
      <material
        name="">
        <color
          rgba="1 1 1 1" />
      </material>
    </visual>
    <collision>
      <origin
        xyz="0 0 0"
        rpy="0 0 0" />
      <geometry>
        <mesh
          filename="package://wheeltec_robot_urdf/meshes/autoware_top_akm_dual_antenna_meshes/right_mushroom_link.STL" />
      </geometry>
    </collision>
  </link>
  <joint
    name="right_mushroom_joint"
    type="fixed">
    <origin
      xyz="-0.13897 -0.26016 0.4187"
      rpy="0 0 0" />
    <parent
      link="base_link" />
    <child
      link="right_mushroom_link" />
    <axis
      xyz="0 0 0" />
  </joint>
</robot>
