<?xml version="1.0" encoding="utf-8"?>
<!-- This URDF was automatically created by SolidWorks to URDF Exporter! Originally created by Stephen Brawner (brawner@gmail.com) 
     Commit Version: 1.6.0-4-g7f85cfe  Build Version: 1.6.7995.38578
     For more information, please see http://wiki.ros.org/sw_urdf_exporter -->
<robot
  name="mec_4wd">
  <link
    name="base_link">
    <inertial>
      <origin
        xyz="-0.0385182112124468 0.00140733003745149 0.12815733674168"
        rpy="0 0 0" />
      <mass
        value="5.2092212049355" />
      <inertia
        ixx="0.0825693826040625"
        ixy="0.000149244809494199"
        ixz="-0.00116373756279965"
        iyy="0.0805339507733737"
        iyz="0.000116560263864275"
        izz="0.156583625303046" />
    </inertial>
    <visual>
      <origin
        xyz="0 0 0"
        rpy="0 0 0" />
      <geometry>
        <mesh
          filename="package://wheeltec_robot_urdf/meshes/flagship_mec_dl_robot_meshes/base_link.STL" />
      </geometry>
      <material
        name="">
        <color
          rgba="0.741176470588235 0.901960784313726 0.956862745098039 1" />
      </material>
    </visual>
    <collision>
      <origin
        xyz="0 0 0"
        rpy="0 0 0" />
      <geometry>
        <mesh
          filename="package://wheeltec_robot_urdf/meshes/flagship_mec_dl_robot_meshes/base_link.STL" />
      </geometry>
    </collision>
  </link>
  <link
    name="controller_link">
    <inertial>
      <origin
        xyz="0.0349782325134063 0.0354906727557576 -0.0933944882253789"
        rpy="0 0 0" />
      <mass
        value="13.7497679689941" />
      <inertia
        ixx="0.372672259515749"
        ixy="-0.00152726371611815"
        ixz="0.0238104845781645"
        iyy="0.463511167576731"
        iyz="-0.000604933691990789"
        izz="0.68901162170127" />
    </inertial>
    <visual>
      <origin
        xyz="0 0 0"
        rpy="0 0 0" />
      <geometry>
        <mesh
          filename="package://wheeltec_robot_urdf/meshes/flagship_mec_dl_robot_meshes/controller_link.STL" />
      </geometry>
      <material
        name="">
        <color
          rgba="0.741176470588235 0.901960784313726 0.956862745098039 1" />
      </material>
    </visual>
    <collision>
      <origin
        xyz="0 0 0"
        rpy="0 0 0" />
      <geometry>
        <mesh
          filename="package://wheeltec_robot_urdf/meshes/flagship_mec_dl_robot_meshes/controller_link.STL" />
      </geometry>
    </collision>
  </link>
  <joint
    name="controller_joint"
    type="fixed">
    <origin
      xyz="-0.03596 -0.036589 0.1798"
      rpy="0 0 0" />
    <parent
      link="base_link" />
    <child
      link="controller_link" />
    <axis
      xyz="0 0 0" />
  </joint>
  <link
    name="camera_link">
    <inertial>
      <origin
        xyz="-4.27512554246334E-08 -3.48614406050848E-07 1.07624260753392E-07"
        rpy="0 0 0" />
      <mass
        value="0.0559842512077705" />
      <inertia
        ixx="0.000130810959338941"
        ixy="1.20255128268298E-07"
        ixz="1.62335437078697E-06"
        iyy="1.91148634967614E-05"
        iyz="-2.80016756385598E-08"
        izz="0.000131387469522753" />
    </inertial>
    <visual>
      <origin
        xyz="0 0 0"
        rpy="0 0 0" />
      <geometry>
        <mesh
          filename="package://wheeltec_robot_urdf/meshes/flagship_mec_dl_robot_meshes/camera_link.STL" />
      </geometry>
      <material
        name="">
        <color
          rgba="1 1 1 1" />
      </material>
    </visual>
    <collision>
      <origin
        xyz="0 0 0"
        rpy="0 0 0" />
      <geometry>
        <mesh
          filename="package://wheeltec_robot_urdf/meshes/flagship_mec_dl_robot_meshes/camera_link.STL" />
      </geometry>
    </collision>
  </link>
  <joint
    name="camera_joint"
    type="fixed">
    <origin
      xyz="0.26489 -0.001222 0.1659"
      rpy="0 0 0" />
    <parent
      link="base_link" />
    <child
      link="camera_link" />
    <axis
      xyz="0 0 0" />
  </joint>
  <link
    name="laser_link">
    <inertial>
      <origin
        xyz="-0.000792227311922744 1.33119304358804E-06 -0.0296756284342814"
        rpy="0 0 0" />
      <mass
        value="0.118401562999932" />
      <inertia
        ixx="0.000132583547441078"
        ixy="-2.17388474590301E-09"
        ixz="-1.07082621762921E-06"
        iyy="0.000135451246710614"
        iyz="-7.24378125813245E-10"
        izz="0.000208462359455448" />
    </inertial>
    <visual>
      <origin
        xyz="0 0 0"
        rpy="0 0 0" />
      <geometry>
        <mesh
          filename="package://wheeltec_robot_urdf/meshes/flagship_mec_dl_robot_meshes/laser_link.STL" />
      </geometry>
      <material
        name="">
        <color
          rgba="1 1 1 1" />
      </material>
    </visual>
    <collision>
      <origin
        xyz="0 0 0"
        rpy="0 0 0" />
      <geometry>
        <mesh
          filename="package://wheeltec_robot_urdf/meshes/flagship_mec_dl_robot_meshes/laser_link.STL" />
      </geometry>
    </collision>
  </link>
  <joint
    name="laser_joint"
    type="fixed">
    <origin
      xyz="0.132555813230632 -0.00130000000000264 0.2896"
      rpy="0 0 0" />
    <parent
      link="base_link" />
    <child
      link="laser_link" />
    <axis
      xyz="0 0 0" />
  </joint>
  <link
    name="lf_wheel_link">
    <inertial>
      <origin
        xyz="-1.23007128643993E-06 -0.00443251392438576 -2.52509476023066E-07"
        rpy="0 0 0" />
      <mass
        value="0.252933438240059" />
      <inertia
        ixx="0.000462600798676089"
        ixy="-2.49294463389071E-08"
        ixz="-5.87830271464204E-08"
        iyy="0.000872204139758246"
        iyz="2.36302161064355E-07"
        izz="0.000463150385470824" />
    </inertial>
    <visual>
      <origin
        xyz="0 0 0"
        rpy="0 0 0" />
      <geometry>
        <mesh
          filename="package://wheeltec_robot_urdf/meshes/flagship_mec_dl_robot_meshes/lf_wheel_link.STL" />
      </geometry>
      <material
        name="">
        <color
          rgba="1 1 1 1" />
      </material>
    </visual>
    <collision>
      <origin
        xyz="0 0 0"
        rpy="0 0 0" />
      <geometry>
        <mesh
          filename="package://wheeltec_robot_urdf/meshes/flagship_mec_dl_robot_meshes/lf_wheel_link.STL" />
      </geometry>
    </collision>
  </link>
  <joint
    name="lf_wheel_joint"
    type="continuous">
    <origin
      xyz="0.177018162984322 0.293928000000001 0.037983"
      rpy="0 0 0" />
    <parent
      link="base_link" />
    <child
      link="lf_wheel_link" />
    <axis
      xyz="0 -1 0" />
  </joint>
  <link
    name="lb_wheel_link">
    <inertial>
      <origin
        xyz="-1.79549139484037E-06 -0.00460588894371011 -1.42325015509148E-07"
        rpy="0 0 0" />
      <mass
        value="0.247565401061819" />
      <inertia
        ixx="0.000450210228639961"
        ixy="2.5137406934399E-08"
        ixz="-5.76099794902906E-08"
        iyy="0.00084792182997602"
        iyz="-2.36040828261662E-07"
        izz="0.000450756322806282" />
    </inertial>
    <visual>
      <origin
        xyz="0 0 0"
        rpy="0 0 0" />
      <geometry>
        <mesh
          filename="package://wheeltec_robot_urdf/meshes/flagship_mec_dl_robot_meshes/lb_wheel_link.STL" />
      </geometry>
      <material
        name="">
        <color
          rgba="1 1 1 1" />
      </material>
    </visual>
    <collision>
      <origin
        xyz="0 0 0"
        rpy="0 0 0" />
      <geometry>
        <mesh
          filename="package://wheeltec_robot_urdf/meshes/flagship_mec_dl_robot_meshes/lb_wheel_link.STL" />
      </geometry>
    </collision>
  </link>
  <joint
    name="lb_wheel_joint"
    type="continuous">
    <origin
      xyz="-0.17498 0.29447 0.037983"
      rpy="0 0 0" />
    <parent
      link="base_link" />
    <child
      link="lb_wheel_link" />
    <axis
      xyz="0 1 0" />
  </joint>
  <link
    name="rb_wheel_link">
    <inertial>
      <origin
        xyz="-1.18600560880533E-06 0.00450894783318911 -2.45703136267372E-07"
        rpy="0 0 0" />
      <mass
        value="0.252933431609788" />
      <inertia
        ixx="0.000462600795641804"
        ixy="-2.49292376227619E-08"
        ixz="-5.87767098320041E-08"
        iyy="0.000872204139451522"
        iyz="2.36301279359248E-07"
        izz="0.000463150387394281" />
    </inertial>
    <visual>
      <origin
        xyz="0 0 0"
        rpy="0 0 0" />
      <geometry>
        <mesh
          filename="package://wheeltec_robot_urdf/meshes/flagship_mec_dl_robot_meshes/rb_wheel_link.STL" />
      </geometry>
      <material
        name="">
        <color
          rgba="1 1 1 1" />
      </material>
    </visual>
    <collision>
      <origin
        xyz="0 0 0"
        rpy="0 0 0" />
      <geometry>
        <mesh
          filename="package://wheeltec_robot_urdf/meshes/flagship_mec_dl_robot_meshes/rb_wheel_link.STL" />
      </geometry>
    </collision>
  </link>
  <joint
    name="rb_wheel_joint"
    type="continuous">
    <origin
      xyz="-0.17498 -0.29707 0.037983"
      rpy="0 0 0" />
    <parent
      link="base_link" />
    <child
      link="rb_wheel_link" />
    <axis
      xyz="0 1 0" />
  </joint>
  <link
    name="rf_wheel_link">
    <inertial>
      <origin
        xyz="1.85537837943395E-06 0.00460582493330264 -1.39995347467337E-07"
        rpy="0 0 0" />
      <mass
        value="0.247566594964803" />
      <inertia
        ixx="0.000450209955287955"
        ixy="2.52315145055208E-08"
        ixz="5.76029225589523E-08"
        iyy="0.000847921905106102"
        iyz="2.36042356751197E-07"
        izz="0.000450756678980562" />
    </inertial>
    <visual>
      <origin
        xyz="0 0 0"
        rpy="0 0 0" />
      <geometry>
        <mesh
          filename="package://wheeltec_robot_urdf/meshes/flagship_mec_dl_robot_meshes/rf_wheel_link.STL" />
      </geometry>
      <material
        name="">
        <color
          rgba="1 1 1 1" />
      </material>
    </visual>
    <collision>
      <origin
        xyz="0 0 0"
        rpy="0 0 0" />
      <geometry>
        <mesh
          filename="package://wheeltec_robot_urdf/meshes/flagship_mec_dl_robot_meshes/rf_wheel_link.STL" />
      </geometry>
    </collision>
  </link>
  <joint
    name="rf_wheel_joint"
    type="continuous">
    <origin
      xyz="0.17701 -0.29707 0.037983"
      rpy="0 0 0" />
    <parent
      link="base_link" />
    <child
      link="rf_wheel_link" />
    <axis
      xyz="0 -1 0" />
  </joint>
</robot>